new image used
new image used
old image used
new image used
old image used
new image used
new image used
new image used
new image used
new image used
new image used
new image used
An error occurred: Reimagine API error: 400 - The request field image_file value is invalid: image resolution exceeds the maximum width of 1024 pixels
Traceback (most recent call last):
  File "D:\rimor\character-generator\app.py", line 646, in index
    reimagined_variations = reimagine_image(file_stream)
                            ^^^^^^^^^^^^^^^^^^^^^^^^^^^^
  File "D:\rimor\character-generator\app.py", line 746, in reimagine_image
    raise Exception(f"Reimagine API error: {response.status_code} - {error_message}")
Exception: Reimagine API error: 400 - The request field image_file value is invalid: image resolution exceeds the maximum width of 1024 pixels
new image used
new image used
new image used
new image used
An error occurred: Reimagine API error: 400 - The request field image_file value is invalid: image file is corrupted or in an unsupported format
Traceback (most recent call last):
  File "D:\rimor\character-generator\app.py", line 646, in index
    reimagined_variations = reimagine_image(file_stream)
                            ^^^^^^^^^^^^^^^^^^^^^^^^^^^^
  File "D:\rimor\character-generator\app.py", line 746, in reimagine_image
    raise Exception(f"Reimagine API error: {response.status_code} - {error_message}")
Exception: Reimagine API error: 400 - The request field image_file value is invalid: image file is corrupted or in an unsupported format
new image used
new image used
old image used
new image used
old image used
new image used
old image used
new image used
old image used
new image used
old image used
new image used
old image used
new image used
new image used
new image used
An error occurred: Reimagine API error: 400 - The request field image_file value is invalid: image resolution exceeds the maximum width of 1024 pixels
Traceback (most recent call last):
  File "D:\rimor\character-generator\app.py", line 646, in index
    reimagined_variations = reimagine_image(file_stream)
                            ^^^^^^^^^^^^^^^^^^^^^^^^^^^^
  File "D:\rimor\character-generator\app.py", line 742, in reimagine_image
    raise Exception(f"Reimagine API error: {response.status_code} - {error_message}")
Exception: Reimagine API error: 400 - The request field image_file value is invalid: image resolution exceeds the maximum width of 1024 pixels
old image used
new image used
old image used
new image used
Exception on /generate [GET]
Traceback (most recent call last):
  File "C:\Users\acer\AppData\Local\Programs\Python\Python311\Lib\site-packages\flask\app.py", line 1455, in wsgi_app
    response = self.full_dispatch_request()
               ^^^^^^^^^^^^^^^^^^^^^^^^^^^^
  File "C:\Users\acer\AppData\Local\Programs\Python\Python311\Lib\site-packages\flask\app.py", line 869, in full_dispatch_request
    rv = self.handle_user_exception(e)
         ^^^^^^^^^^^^^^^^^^^^^^^^^^^^^
  File "C:\Users\acer\AppData\Local\Programs\Python\Python311\Lib\site-packages\flask\app.py", line 867, in full_dispatch_request
    rv = self.dispatch_request()
         ^^^^^^^^^^^^^^^^^^^^^^^
  File "C:\Users\acer\AppData\Local\Programs\Python\Python311\Lib\site-packages\flask\app.py", line 852, in dispatch_request
    return self.ensure_sync(self.view_functions[rule.endpoint])(**view_args)
           ^^^^^^^^^^^^^^^^^^^^^^^^^^^^^^^^^^^^^^^^^^^^^^^^^^^^^^^^^^^^^^^^^
  File "D:\rimor\character-generator\app.py", line 443, in generate
    return render_template('index.html', message="Kindly login to your account!", models=session['models'], user_permissions= session['permissions'])
                                                                                         ~~~~~~~^^^^^^^^^^
  File "C:\Users\acer\AppData\Local\Programs\Python\Python311\Lib\site-packages\flask\sessions.py", line 79, in __getitem__
    return super().__getitem__(key)
           ^^^^^^^^^^^^^^^^^^^^^^^^
KeyError: 'models'
Exception on /generate [GET]
Traceback (most recent call last):
  File "C:\Users\acer\AppData\Local\Programs\Python\Python311\Lib\site-packages\flask\app.py", line 1455, in wsgi_app
    response = self.full_dispatch_request()
               ^^^^^^^^^^^^^^^^^^^^^^^^^^^^
  File "C:\Users\acer\AppData\Local\Programs\Python\Python311\Lib\site-packages\flask\app.py", line 869, in full_dispatch_request
    rv = self.handle_user_exception(e)
         ^^^^^^^^^^^^^^^^^^^^^^^^^^^^^
  File "C:\Users\acer\AppData\Local\Programs\Python\Python311\Lib\site-packages\flask\app.py", line 867, in full_dispatch_request
    rv = self.dispatch_request()
         ^^^^^^^^^^^^^^^^^^^^^^^
  File "C:\Users\acer\AppData\Local\Programs\Python\Python311\Lib\site-packages\flask\app.py", line 852, in dispatch_request
    return self.ensure_sync(self.view_functions[rule.endpoint])(**view_args)
           ^^^^^^^^^^^^^^^^^^^^^^^^^^^^^^^^^^^^^^^^^^^^^^^^^^^^^^^^^^^^^^^^^
  File "D:\rimor\character-generator\app.py", line 443, in generate
    return render_template('index.html', message="Kindly login to your account!", models=session['models'], user_permissions= session['permissions'])
                                                                                         ~~~~~~~^^^^^^^^^^
  File "C:\Users\acer\AppData\Local\Programs\Python\Python311\Lib\site-packages\flask\sessions.py", line 79, in __getitem__
    return super().__getitem__(key)
           ^^^^^^^^^^^^^^^^^^^^^^^^
KeyError: 'models'
Exception on /generate [GET]
Traceback (most recent call last):
  File "C:\Users\acer\AppData\Local\Programs\Python\Python311\Lib\site-packages\flask\app.py", line 1455, in wsgi_app
    response = self.full_dispatch_request()
               ^^^^^^^^^^^^^^^^^^^^^^^^^^^^
  File "C:\Users\acer\AppData\Local\Programs\Python\Python311\Lib\site-packages\flask\app.py", line 869, in full_dispatch_request
    rv = self.handle_user_exception(e)
         ^^^^^^^^^^^^^^^^^^^^^^^^^^^^^
  File "C:\Users\acer\AppData\Local\Programs\Python\Python311\Lib\site-packages\flask\app.py", line 867, in full_dispatch_request
    rv = self.dispatch_request()
         ^^^^^^^^^^^^^^^^^^^^^^^
  File "C:\Users\acer\AppData\Local\Programs\Python\Python311\Lib\site-packages\flask\app.py", line 852, in dispatch_request
    return self.ensure_sync(self.view_functions[rule.endpoint])(**view_args)
           ^^^^^^^^^^^^^^^^^^^^^^^^^^^^^^^^^^^^^^^^^^^^^^^^^^^^^^^^^^^^^^^^^
  File "D:\rimor\character-generator\app.py", line 443, in generate
    return render_template('index.html', message="Kindly login to your account!", models=session['models'], user_permissions= session['permissions'])
                                                                                         ~~~~~~~^^^^^^^^^^
  File "C:\Users\acer\AppData\Local\Programs\Python\Python311\Lib\site-packages\flask\sessions.py", line 79, in __getitem__
    return super().__getitem__(key)
           ^^^^^^^^^^^^^^^^^^^^^^^^
KeyError: 'models'
new image used
new image used
new image used
new image used
An error occurred: Reimagine API error: 400 - The request field image_file value is invalid: image resolution exceeds the maximum width of 1024 pixels
Traceback (most recent call last):
  File "D:\rimor\character-generator\app.py", line 647, in index
    reimagined_variations = reimagine_image(file_stream)
                            ^^^^^^^^^^^^^^^^^^^^^^^^^^^^
  File "D:\rimor\character-generator\app.py", line 743, in reimagine_image
    raise Exception(f"Reimagine API error: {response.status_code} - {error_message}")
Exception: Reimagine API error: 400 - The request field image_file value is invalid: image resolution exceeds the maximum width of 1024 pixels
old image used
new image used
old image used
new image used
new image used
new image used
old image used
new image used
new image used
old image used
new image used
old image used
new image used
old image used
new image used
An error occurred: Reimagine API error: 400 - The request field image_file value is invalid: image resolution exceeds the maximum width of 1024 pixels
Traceback (most recent call last):
  File "D:\rimor\character-generator\app.py", line 647, in index
    reimagined_variations = reimagine_image(file_stream)
                            ^^^^^^^^^^^^^^^^^^^^^^^^^^^^
  File "D:\rimor\character-generator\app.py", line 743, in reimagine_image
    raise Exception(f"Reimagine API error: {response.status_code} - {error_message}")
Exception: Reimagine API error: 400 - The request field image_file value is invalid: image resolution exceeds the maximum width of 1024 pixels
old image used
An error occurred: Reimagine API error: 400 - The request field image_file value is invalid: image resolution exceeds the maximum width of 1024 pixels
Traceback (most recent call last):
  File "D:\rimor\character-generator\app.py", line 647, in index
    reimagined_variations = reimagine_image(file_stream)
                            ^^^^^^^^^^^^^^^^^^^^^^^^^^^^
  File "D:\rimor\character-generator\app.py", line 743, in reimagine_image
    raise Exception(f"Reimagine API error: {response.status_code} - {error_message}")
Exception: Reimagine API error: 400 - The request field image_file value is invalid: image resolution exceeds the maximum width of 1024 pixels
new image used
