Exception on /removebg [POST]
Traceback (most recent call last):
  File "C:\Users\acer\AppData\Local\Programs\Python\Python311\Lib\site-packages\flask\app.py", line 1455, in wsgi_app
    response = self.full_dispatch_request()
               ^^^^^^^^^^^^^^^^^^^^^^^^^^^^
  File "C:\Users\acer\AppData\Local\Programs\Python\Python311\Lib\site-packages\flask\app.py", line 869, in full_dispatch_request
    rv = self.handle_user_exception(e)
         ^^^^^^^^^^^^^^^^^^^^^^^^^^^^^
  File "C:\Users\acer\AppData\Local\Programs\Python\Python311\Lib\site-packages\flask\app.py", line 867, in full_dispatch_request
    rv = self.dispatch_request()
         ^^^^^^^^^^^^^^^^^^^^^^^
  File "C:\Users\acer\AppData\Local\Programs\Python\Python311\Lib\site-packages\flask\app.py", line 852, in dispatch_request
    return self.ensure_sync(self.view_functions[rule.endpoint])(**view_args)
           ^^^^^^^^^^^^^^^^^^^^^^^^^^^^^^^^^^^^^^^^^^^^^^^^^^^^^^^^^^^^^^^^^
  File "D:\rimor\character-generator\app.py", line 529, in removebg
    file.save(file_path)
  File "C:\Users\acer\AppData\Local\Programs\Python\Python311\Lib\site-packages\werkzeug\datastructures\file_storage.py", line 125, in save
    dst = open(dst, "wb")
          ^^^^^^^^^^^^^^^
FileNotFoundError: [Errno 2] No such file or directory: './static/images/out/IMG_20210123_174040.jpg'
Exception on /removebg [POST]
Traceback (most recent call last):
  File "C:\Users\acer\AppData\Local\Programs\Python\Python311\Lib\site-packages\flask\app.py", line 1455, in wsgi_app
    response = self.full_dispatch_request()
               ^^^^^^^^^^^^^^^^^^^^^^^^^^^^
  File "C:\Users\acer\AppData\Local\Programs\Python\Python311\Lib\site-packages\flask\app.py", line 869, in full_dispatch_request
    rv = self.handle_user_exception(e)
         ^^^^^^^^^^^^^^^^^^^^^^^^^^^^^
  File "C:\Users\acer\AppData\Local\Programs\Python\Python311\Lib\site-packages\flask\app.py", line 867, in full_dispatch_request
    rv = self.dispatch_request()
         ^^^^^^^^^^^^^^^^^^^^^^^
  File "C:\Users\acer\AppData\Local\Programs\Python\Python311\Lib\site-packages\flask\app.py", line 852, in dispatch_request
    return self.ensure_sync(self.view_functions[rule.endpoint])(**view_args)
           ^^^^^^^^^^^^^^^^^^^^^^^^^^^^^^^^^^^^^^^^^^^^^^^^^^^^^^^^^^^^^^^^^
  File "D:\rimor\character-generator\app.py", line 529, in removebg
    file.save(file_path)
  File "C:\Users\acer\AppData\Local\Programs\Python\Python311\Lib\site-packages\werkzeug\datastructures\file_storage.py", line 125, in save
    dst = open(dst, "wb")
          ^^^^^^^^^^^^^^^
FileNotFoundError: [Errno 2] No such file or directory: './static/images/out/IMG_20210123_174040.jpg'
Exception on /removebg [POST]
Traceback (most recent call last):
  File "C:\Users\acer\AppData\Local\Programs\Python\Python311\Lib\site-packages\flask\app.py", line 1455, in wsgi_app
    response = self.full_dispatch_request()
               ^^^^^^^^^^^^^^^^^^^^^^^^^^^^
  File "C:\Users\acer\AppData\Local\Programs\Python\Python311\Lib\site-packages\flask\app.py", line 869, in full_dispatch_request
    rv = self.handle_user_exception(e)
         ^^^^^^^^^^^^^^^^^^^^^^^^^^^^^
  File "C:\Users\acer\AppData\Local\Programs\Python\Python311\Lib\site-packages\flask\app.py", line 867, in full_dispatch_request
    rv = self.dispatch_request()
         ^^^^^^^^^^^^^^^^^^^^^^^
  File "C:\Users\acer\AppData\Local\Programs\Python\Python311\Lib\site-packages\flask\app.py", line 852, in dispatch_request
    return self.ensure_sync(self.view_functions[rule.endpoint])(**view_args)
           ^^^^^^^^^^^^^^^^^^^^^^^^^^^^^^^^^^^^^^^^^^^^^^^^^^^^^^^^^^^^^^^^^
  File "D:\rimor\character-generator\app.py", line 529, in removebg
    file.save(file_path)
  File "C:\Users\acer\AppData\Local\Programs\Python\Python311\Lib\site-packages\werkzeug\datastructures\file_storage.py", line 125, in save
    dst = open(dst, "wb")
          ^^^^^^^^^^^^^^^
FileNotFoundError: [Errno 2] No such file or directory: './static/images/out/IMG_20210123_174040.jpg'
Exception on /removebg [POST]
Traceback (most recent call last):
  File "C:\Users\acer\AppData\Local\Programs\Python\Python311\Lib\site-packages\flask\app.py", line 1455, in wsgi_app
    response = self.full_dispatch_request()
               ^^^^^^^^^^^^^^^^^^^^^^^^^^^^
  File "C:\Users\acer\AppData\Local\Programs\Python\Python311\Lib\site-packages\flask\app.py", line 869, in full_dispatch_request
    rv = self.handle_user_exception(e)
         ^^^^^^^^^^^^^^^^^^^^^^^^^^^^^
  File "C:\Users\acer\AppData\Local\Programs\Python\Python311\Lib\site-packages\flask\app.py", line 867, in full_dispatch_request
    rv = self.dispatch_request()
         ^^^^^^^^^^^^^^^^^^^^^^^
  File "C:\Users\acer\AppData\Local\Programs\Python\Python311\Lib\site-packages\flask\app.py", line 852, in dispatch_request
    return self.ensure_sync(self.view_functions[rule.endpoint])(**view_args)
           ^^^^^^^^^^^^^^^^^^^^^^^^^^^^^^^^^^^^^^^^^^^^^^^^^^^^^^^^^^^^^^^^^
  File "D:\rimor\character-generator\app.py", line 529, in removebg
    file.save(file_path)
  File "C:\Users\acer\AppData\Local\Programs\Python\Python311\Lib\site-packages\werkzeug\datastructures\file_storage.py", line 125, in save
    dst = open(dst, "wb")
          ^^^^^^^^^^^^^^^
FileNotFoundError: [Errno 2] No such file or directory: './static/images/out/IMG_20210123_174040.jpg'
new image used
An error occurred: Reimagine API error: 400 - The request field image_file value is invalid: image resolution exceeds the maximum height of 1024 pixels
Traceback (most recent call last):
  File "D:\rimor\character-generator\app.py", line 472, in index
    reimagined_variations = reimagine_image(file_stream)
                            ^^^^^^^^^^^^^^^^^^^^^^^^^^^^
  File "D:\rimor\character-generator\app.py", line 567, in reimagine_image
    raise Exception(f"Reimagine API error: {response.status_code} - {error_message}")
Exception: Reimagine API error: 400 - The request field image_file value is invalid: image resolution exceeds the maximum height of 1024 pixels
old image used
An error occurred: Reimagine API error: 400 - The request field image_file value is invalid: image resolution exceeds the maximum height of 1024 pixels
Traceback (most recent call last):
  File "D:\rimor\character-generator\app.py", line 472, in index
    reimagined_variations = reimagine_image(file_stream)
                            ^^^^^^^^^^^^^^^^^^^^^^^^^^^^
  File "D:\rimor\character-generator\app.py", line 567, in reimagine_image
    raise Exception(f"Reimagine API error: {response.status_code} - {error_message}")
Exception: Reimagine API error: 400 - The request field image_file value is invalid: image resolution exceeds the maximum height of 1024 pixels
new image used
An error occurred: Reimagine API error: 400 - The request field image_file value is invalid: image resolution exceeds the maximum height of 1024 pixels
Traceback (most recent call last):
  File "D:\rimor\character-generator\app.py", line 472, in index
    reimagined_variations = reimagine_image(file_stream)
                            ^^^^^^^^^^^^^^^^^^^^^^^^^^^^
  File "D:\rimor\character-generator\app.py", line 567, in reimagine_image
    raise Exception(f"Reimagine API error: {response.status_code} - {error_message}")
Exception: Reimagine API error: 400 - The request field image_file value is invalid: image resolution exceeds the maximum height of 1024 pixels
new image used
old image used
new image used
old image used
